11/10/2017 08:35:36|ERROR|Unexpected error in provider u'addic7ed'|'Traceback (most recent call last):\n  File "C:\\Python27\\lib\\site-packages\\subliminal\\core.py", line 118, in list_subtitles_provider\n    return self[provider].list_subtitles(video, provider_languages)\n  File "C:\\Python27\\lib\\site-packages\\subliminal\\providers\\addic7ed.py", line 273, in list_subtitles\n    return [s for s in self.query(video.series, video.season, video.year)\n  File "C:\\Python27\\lib\\site-packages\\subliminal\\providers\\addic7ed.py", line 228, in query\n    show_id = self.get_show_id(series, year, country)\n  File "C:\\Python27\\lib\\site-packages\\subliminal\\providers\\addic7ed.py", line 201, in get_show_id\n    show_ids = self._get_show_ids()\n  File "C:\\Python27\\lib\\site-packages\\dogpile\\cache\\region.py", line 1231, in decorate\n    should_cache_fn)\n  File "C:\\Python27\\lib\\site-packages\\dogpile\\cache\\region.py", line 833, in get_or_create\n    async_creator) as value:\n  File "C:\\Python27\\lib\\site-packages\\dogpile\\lock.py", line 154, in __enter__\n    return self._enter()\n  File "C:\\Python27\\lib\\site-packages\\dogpile\\lock.py", line 87, in _enter\n    value = value_fn()\n  File "C:\\Python27\\lib\\site-packages\\dogpile\\cache\\region.py", line 788, in get_value\n    value = self.backend.get(key)\n  File "C:\\Python27\\lib\\site-packages\\dogpile\\cache\\backends\\file.py", line 220, in get\n    with self._dbm_file(False) as dbm:\n  File "C:\\Python27\\lib\\contextlib.py", line 17, in __enter__\n    return self.gen.next()\n  File "C:\\Python27\\lib\\site-packages\\dogpile\\cache\\backends\\file.py", line 212, in _dbm_file\n    with self._use_rw_lock(write):\n  File "C:\\Python27\\lib\\contextlib.py", line 17, in __enter__\n    return self.gen.next()\n  File "C:\\Python27\\lib\\site-packages\\dogpile\\cache\\backends\\file.py", line 207, in _use_rw_lock\n    with self._rw_lock.read():\n  File "C:\\Python27\\lib\\contextlib.py", line 17, in __enter__\n    return self.gen.next()\n  File "C:\\Python27\\lib\\site-packages\\dogpile\\cache\\backends\\file.py", line 327, in read\n    self.acquire_read_lock(True)\n  File "C:\\Python27\\lib\\site-packages\\dogpile\\cache\\backends\\file.py", line 408, in acquire_read_lock\n    return self._acquire(wait, os.O_RDONLY, self._module.LOCK_SH)\n  File "C:\\Python27\\lib\\site-packages\\dogpile\\util\\langhelpers.py", line 66, in __get__\n    obj.__dict__[self.__name__] = result = self.fget(obj)\n  File "C:\\Python27\\lib\\site-packages\\dogpile\\cache\\backends\\file.py", line 400, in _module\n    import fcntl\nImportError: No module named fcntl'|
11/10/2017 08:35:40|ERROR|Unexpected error in provider u'addic7ed'|'Traceback (most recent call last):\n  File "C:\\Python27\\lib\\site-packages\\subliminal\\core.py", line 118, in list_subtitles_provider\n    return self[provider].list_subtitles(video, provider_languages)\n  File "C:\\Python27\\lib\\site-packages\\subliminal\\providers\\addic7ed.py", line 273, in list_subtitles\n    return [s for s in self.query(video.series, video.season, video.year)\n  File "C:\\Python27\\lib\\site-packages\\subliminal\\providers\\addic7ed.py", line 228, in query\n    show_id = self.get_show_id(series, year, country)\n  File "C:\\Python27\\lib\\site-packages\\subliminal\\providers\\addic7ed.py", line 201, in get_show_id\n    show_ids = self._get_show_ids()\n  File "C:\\Python27\\lib\\site-packages\\dogpile\\cache\\region.py", line 1231, in decorate\n    should_cache_fn)\n  File "C:\\Python27\\lib\\site-packages\\dogpile\\cache\\region.py", line 833, in get_or_create\n    async_creator) as value:\n  File "C:\\Python27\\lib\\site-packages\\dogpile\\lock.py", line 154, in __enter__\n    return self._enter()\n  File "C:\\Python27\\lib\\site-packages\\dogpile\\lock.py", line 87, in _enter\n    value = value_fn()\n  File "C:\\Python27\\lib\\site-packages\\dogpile\\cache\\region.py", line 788, in get_value\n    value = self.backend.get(key)\n  File "C:\\Python27\\lib\\site-packages\\dogpile\\cache\\backends\\file.py", line 220, in get\n    with self._dbm_file(False) as dbm:\n  File "C:\\Python27\\lib\\contextlib.py", line 17, in __enter__\n    return self.gen.next()\n  File "C:\\Python27\\lib\\site-packages\\dogpile\\cache\\backends\\file.py", line 212, in _dbm_file\n    with self._use_rw_lock(write):\n  File "C:\\Python27\\lib\\contextlib.py", line 17, in __enter__\n    return self.gen.next()\n  File "C:\\Python27\\lib\\site-packages\\dogpile\\cache\\backends\\file.py", line 207, in _use_rw_lock\n    with self._rw_lock.read():\n  File "C:\\Python27\\lib\\contextlib.py", line 17, in __enter__\n    return self.gen.next()\n  File "C:\\Python27\\lib\\site-packages\\dogpile\\cache\\backends\\file.py", line 327, in read\n    self.acquire_read_lock(True)\n  File "C:\\Python27\\lib\\site-packages\\dogpile\\cache\\backends\\file.py", line 408, in acquire_read_lock\n    return self._acquire(wait, os.O_RDONLY, self._module.LOCK_SH)\n  File "C:\\Python27\\lib\\site-packages\\dogpile\\util\\langhelpers.py", line 66, in __get__\n    obj.__dict__[self.__name__] = result = self.fget(obj)\n  File "C:\\Python27\\lib\\site-packages\\dogpile\\cache\\backends\\file.py", line 400, in _module\n    import fcntl\nImportError: No module named fcntl'|
11/10/2017 08:35:44|ERROR|Unexpected error in provider u'addic7ed'|'Traceback (most recent call last):\n  File "C:\\Python27\\lib\\site-packages\\subliminal\\core.py", line 118, in list_subtitles_provider\n    return self[provider].list_subtitles(video, provider_languages)\n  File "C:\\Python27\\lib\\site-packages\\subliminal\\providers\\addic7ed.py", line 273, in list_subtitles\n    return [s for s in self.query(video.series, video.season, video.year)\n  File "C:\\Python27\\lib\\site-packages\\subliminal\\providers\\addic7ed.py", line 228, in query\n    show_id = self.get_show_id(series, year, country)\n  File "C:\\Python27\\lib\\site-packages\\subliminal\\providers\\addic7ed.py", line 201, in get_show_id\n    show_ids = self._get_show_ids()\n  File "C:\\Python27\\lib\\site-packages\\dogpile\\cache\\region.py", line 1231, in decorate\n    should_cache_fn)\n  File "C:\\Python27\\lib\\site-packages\\dogpile\\cache\\region.py", line 833, in get_or_create\n    async_creator) as value:\n  File "C:\\Python27\\lib\\site-packages\\dogpile\\lock.py", line 154, in __enter__\n    return self._enter()\n  File "C:\\Python27\\lib\\site-packages\\dogpile\\lock.py", line 87, in _enter\n    value = value_fn()\n  File "C:\\Python27\\lib\\site-packages\\dogpile\\cache\\region.py", line 788, in get_value\n    value = self.backend.get(key)\n  File "C:\\Python27\\lib\\site-packages\\dogpile\\cache\\backends\\file.py", line 220, in get\n    with self._dbm_file(False) as dbm:\n  File "C:\\Python27\\lib\\contextlib.py", line 17, in __enter__\n    return self.gen.next()\n  File "C:\\Python27\\lib\\site-packages\\dogpile\\cache\\backends\\file.py", line 212, in _dbm_file\n    with self._use_rw_lock(write):\n  File "C:\\Python27\\lib\\contextlib.py", line 17, in __enter__\n    return self.gen.next()\n  File "C:\\Python27\\lib\\site-packages\\dogpile\\cache\\backends\\file.py", line 207, in _use_rw_lock\n    with self._rw_lock.read():\n  File "C:\\Python27\\lib\\contextlib.py", line 17, in __enter__\n    return self.gen.next()\n  File "C:\\Python27\\lib\\site-packages\\dogpile\\cache\\backends\\file.py", line 327, in read\n    self.acquire_read_lock(True)\n  File "C:\\Python27\\lib\\site-packages\\dogpile\\cache\\backends\\file.py", line 408, in acquire_read_lock\n    return self._acquire(wait, os.O_RDONLY, self._module.LOCK_SH)\n  File "C:\\Python27\\lib\\site-packages\\dogpile\\util\\langhelpers.py", line 66, in __get__\n    obj.__dict__[self.__name__] = result = self.fget(obj)\n  File "C:\\Python27\\lib\\site-packages\\dogpile\\cache\\backends\\file.py", line 400, in _module\n    import fcntl\nImportError: No module named fcntl'|
11/10/2017 08:35:49|ERROR|Unexpected error in provider u'addic7ed'|'Traceback (most recent call last):\n  File "C:\\Python27\\lib\\site-packages\\subliminal\\core.py", line 118, in list_subtitles_provider\n    return self[provider].list_subtitles(video, provider_languages)\n  File "C:\\Python27\\lib\\site-packages\\subliminal\\providers\\addic7ed.py", line 273, in list_subtitles\n    return [s for s in self.query(video.series, video.season, video.year)\n  File "C:\\Python27\\lib\\site-packages\\subliminal\\providers\\addic7ed.py", line 228, in query\n    show_id = self.get_show_id(series, year, country)\n  File "C:\\Python27\\lib\\site-packages\\subliminal\\providers\\addic7ed.py", line 201, in get_show_id\n    show_ids = self._get_show_ids()\n  File "C:\\Python27\\lib\\site-packages\\dogpile\\cache\\region.py", line 1231, in decorate\n    should_cache_fn)\n  File "C:\\Python27\\lib\\site-packages\\dogpile\\cache\\region.py", line 833, in get_or_create\n    async_creator) as value:\n  File "C:\\Python27\\lib\\site-packages\\dogpile\\lock.py", line 154, in __enter__\n    return self._enter()\n  File "C:\\Python27\\lib\\site-packages\\dogpile\\lock.py", line 87, in _enter\n    value = value_fn()\n  File "C:\\Python27\\lib\\site-packages\\dogpile\\cache\\region.py", line 788, in get_value\n    value = self.backend.get(key)\n  File "C:\\Python27\\lib\\site-packages\\dogpile\\cache\\backends\\file.py", line 220, in get\n    with self._dbm_file(False) as dbm:\n  File "C:\\Python27\\lib\\contextlib.py", line 17, in __enter__\n    return self.gen.next()\n  File "C:\\Python27\\lib\\site-packages\\dogpile\\cache\\backends\\file.py", line 212, in _dbm_file\n    with self._use_rw_lock(write):\n  File "C:\\Python27\\lib\\contextlib.py", line 17, in __enter__\n    return self.gen.next()\n  File "C:\\Python27\\lib\\site-packages\\dogpile\\cache\\backends\\file.py", line 207, in _use_rw_lock\n    with self._rw_lock.read():\n  File "C:\\Python27\\lib\\contextlib.py", line 17, in __enter__\n    return self.gen.next()\n  File "C:\\Python27\\lib\\site-packages\\dogpile\\cache\\backends\\file.py", line 327, in read\n    self.acquire_read_lock(True)\n  File "C:\\Python27\\lib\\site-packages\\dogpile\\cache\\backends\\file.py", line 408, in acquire_read_lock\n    return self._acquire(wait, os.O_RDONLY, self._module.LOCK_SH)\n  File "C:\\Python27\\lib\\site-packages\\dogpile\\util\\langhelpers.py", line 66, in __get__\n    obj.__dict__[self.__name__] = result = self.fget(obj)\n  File "C:\\Python27\\lib\\site-packages\\dogpile\\cache\\backends\\file.py", line 400, in _module\n    import fcntl\nImportError: No module named fcntl'|
11/10/2017 08:35:53|ERROR|Unexpected error in provider u'addic7ed'|'Traceback (most recent call last):\n  File "C:\\Python27\\lib\\site-packages\\subliminal\\core.py", line 118, in list_subtitles_provider\n    return self[provider].list_subtitles(video, provider_languages)\n  File "C:\\Python27\\lib\\site-packages\\subliminal\\providers\\addic7ed.py", line 273, in list_subtitles\n    return [s for s in self.query(video.series, video.season, video.year)\n  File "C:\\Python27\\lib\\site-packages\\subliminal\\providers\\addic7ed.py", line 228, in query\n    show_id = self.get_show_id(series, year, country)\n  File "C:\\Python27\\lib\\site-packages\\subliminal\\providers\\addic7ed.py", line 201, in get_show_id\n    show_ids = self._get_show_ids()\n  File "C:\\Python27\\lib\\site-packages\\dogpile\\cache\\region.py", line 1231, in decorate\n    should_cache_fn)\n  File "C:\\Python27\\lib\\site-packages\\dogpile\\cache\\region.py", line 833, in get_or_create\n    async_creator) as value:\n  File "C:\\Python27\\lib\\site-packages\\dogpile\\lock.py", line 154, in __enter__\n    return self._enter()\n  File "C:\\Python27\\lib\\site-packages\\dogpile\\lock.py", line 87, in _enter\n    value = value_fn()\n  File "C:\\Python27\\lib\\site-packages\\dogpile\\cache\\region.py", line 788, in get_value\n    value = self.backend.get(key)\n  File "C:\\Python27\\lib\\site-packages\\dogpile\\cache\\backends\\file.py", line 220, in get\n    with self._dbm_file(False) as dbm:\n  File "C:\\Python27\\lib\\contextlib.py", line 17, in __enter__\n    return self.gen.next()\n  File "C:\\Python27\\lib\\site-packages\\dogpile\\cache\\backends\\file.py", line 212, in _dbm_file\n    with self._use_rw_lock(write):\n  File "C:\\Python27\\lib\\contextlib.py", line 17, in __enter__\n    return self.gen.next()\n  File "C:\\Python27\\lib\\site-packages\\dogpile\\cache\\backends\\file.py", line 207, in _use_rw_lock\n    with self._rw_lock.read():\n  File "C:\\Python27\\lib\\contextlib.py", line 17, in __enter__\n    return self.gen.next()\n  File "C:\\Python27\\lib\\site-packages\\dogpile\\cache\\backends\\file.py", line 327, in read\n    self.acquire_read_lock(True)\n  File "C:\\Python27\\lib\\site-packages\\dogpile\\cache\\backends\\file.py", line 408, in acquire_read_lock\n    return self._acquire(wait, os.O_RDONLY, self._module.LOCK_SH)\n  File "C:\\Python27\\lib\\site-packages\\dogpile\\util\\langhelpers.py", line 66, in __get__\n    obj.__dict__[self.__name__] = result = self.fget(obj)\n  File "C:\\Python27\\lib\\site-packages\\dogpile\\cache\\backends\\file.py", line 400, in _module\n    import fcntl\nImportError: No module named fcntl'|
11/10/2017 08:35:57|ERROR|Unexpected error in provider u'addic7ed'|'Traceback (most recent call last):\n  File "C:\\Python27\\lib\\site-packages\\subliminal\\core.py", line 118, in list_subtitles_provider\n    return self[provider].list_subtitles(video, provider_languages)\n  File "C:\\Python27\\lib\\site-packages\\subliminal\\providers\\addic7ed.py", line 273, in list_subtitles\n    return [s for s in self.query(video.series, video.season, video.year)\n  File "C:\\Python27\\lib\\site-packages\\subliminal\\providers\\addic7ed.py", line 228, in query\n    show_id = self.get_show_id(series, year, country)\n  File "C:\\Python27\\lib\\site-packages\\subliminal\\providers\\addic7ed.py", line 201, in get_show_id\n    show_ids = self._get_show_ids()\n  File "C:\\Python27\\lib\\site-packages\\dogpile\\cache\\region.py", line 1231, in decorate\n    should_cache_fn)\n  File "C:\\Python27\\lib\\site-packages\\dogpile\\cache\\region.py", line 833, in get_or_create\n    async_creator) as value:\n  File "C:\\Python27\\lib\\site-packages\\dogpile\\lock.py", line 154, in __enter__\n    return self._enter()\n  File "C:\\Python27\\lib\\site-packages\\dogpile\\lock.py", line 87, in _enter\n    value = value_fn()\n  File "C:\\Python27\\lib\\site-packages\\dogpile\\cache\\region.py", line 788, in get_value\n    value = self.backend.get(key)\n  File "C:\\Python27\\lib\\site-packages\\dogpile\\cache\\backends\\file.py", line 220, in get\n    with self._dbm_file(False) as dbm:\n  File "C:\\Python27\\lib\\contextlib.py", line 17, in __enter__\n    return self.gen.next()\n  File "C:\\Python27\\lib\\site-packages\\dogpile\\cache\\backends\\file.py", line 212, in _dbm_file\n    with self._use_rw_lock(write):\n  File "C:\\Python27\\lib\\contextlib.py", line 17, in __enter__\n    return self.gen.next()\n  File "C:\\Python27\\lib\\site-packages\\dogpile\\cache\\backends\\file.py", line 207, in _use_rw_lock\n    with self._rw_lock.read():\n  File "C:\\Python27\\lib\\contextlib.py", line 17, in __enter__\n    return self.gen.next()\n  File "C:\\Python27\\lib\\site-packages\\dogpile\\cache\\backends\\file.py", line 327, in read\n    self.acquire_read_lock(True)\n  File "C:\\Python27\\lib\\site-packages\\dogpile\\cache\\backends\\file.py", line 408, in acquire_read_lock\n    return self._acquire(wait, os.O_RDONLY, self._module.LOCK_SH)\n  File "C:\\Python27\\lib\\site-packages\\dogpile\\util\\langhelpers.py", line 66, in __get__\n    obj.__dict__[self.__name__] = result = self.fget(obj)\n  File "C:\\Python27\\lib\\site-packages\\dogpile\\cache\\backends\\file.py", line 400, in _module\n    import fcntl\nImportError: No module named fcntl'|
11/10/2017 08:36:03|ERROR|Unexpected error in provider u'addic7ed'|'Traceback (most recent call last):\n  File "C:\\Python27\\lib\\site-packages\\subliminal\\core.py", line 118, in list_subtitles_provider\n    return self[provider].list_subtitles(video, provider_languages)\n  File "C:\\Python27\\lib\\site-packages\\subliminal\\providers\\addic7ed.py", line 273, in list_subtitles\n    return [s for s in self.query(video.series, video.season, video.year)\n  File "C:\\Python27\\lib\\site-packages\\subliminal\\providers\\addic7ed.py", line 228, in query\n    show_id = self.get_show_id(series, year, country)\n  File "C:\\Python27\\lib\\site-packages\\subliminal\\providers\\addic7ed.py", line 201, in get_show_id\n    show_ids = self._get_show_ids()\n  File "C:\\Python27\\lib\\site-packages\\dogpile\\cache\\region.py", line 1231, in decorate\n    should_cache_fn)\n  File "C:\\Python27\\lib\\site-packages\\dogpile\\cache\\region.py", line 833, in get_or_create\n    async_creator) as value:\n  File "C:\\Python27\\lib\\site-packages\\dogpile\\lock.py", line 154, in __enter__\n    return self._enter()\n  File "C:\\Python27\\lib\\site-packages\\dogpile\\lock.py", line 87, in _enter\n    value = value_fn()\n  File "C:\\Python27\\lib\\site-packages\\dogpile\\cache\\region.py", line 788, in get_value\n    value = self.backend.get(key)\n  File "C:\\Python27\\lib\\site-packages\\dogpile\\cache\\backends\\file.py", line 220, in get\n    with self._dbm_file(False) as dbm:\n  File "C:\\Python27\\lib\\contextlib.py", line 17, in __enter__\n    return self.gen.next()\n  File "C:\\Python27\\lib\\site-packages\\dogpile\\cache\\backends\\file.py", line 212, in _dbm_file\n    with self._use_rw_lock(write):\n  File "C:\\Python27\\lib\\contextlib.py", line 17, in __enter__\n    return self.gen.next()\n  File "C:\\Python27\\lib\\site-packages\\dogpile\\cache\\backends\\file.py", line 207, in _use_rw_lock\n    with self._rw_lock.read():\n  File "C:\\Python27\\lib\\contextlib.py", line 17, in __enter__\n    return self.gen.next()\n  File "C:\\Python27\\lib\\site-packages\\dogpile\\cache\\backends\\file.py", line 327, in read\n    self.acquire_read_lock(True)\n  File "C:\\Python27\\lib\\site-packages\\dogpile\\cache\\backends\\file.py", line 408, in acquire_read_lock\n    return self._acquire(wait, os.O_RDONLY, self._module.LOCK_SH)\n  File "C:\\Python27\\lib\\site-packages\\dogpile\\util\\langhelpers.py", line 66, in __get__\n    obj.__dict__[self.__name__] = result = self.fget(obj)\n  File "C:\\Python27\\lib\\site-packages\\dogpile\\cache\\backends\\file.py", line 400, in _module\n    import fcntl\nImportError: No module named fcntl'|
11/10/2017 08:36:09|ERROR|Unexpected error in provider u'addic7ed'|'Traceback (most recent call last):\n  File "C:\\Python27\\lib\\site-packages\\subliminal\\core.py", line 118, in list_subtitles_provider\n    return self[provider].list_subtitles(video, provider_languages)\n  File "C:\\Python27\\lib\\site-packages\\subliminal\\providers\\addic7ed.py", line 273, in list_subtitles\n    return [s for s in self.query(video.series, video.season, video.year)\n  File "C:\\Python27\\lib\\site-packages\\subliminal\\providers\\addic7ed.py", line 228, in query\n    show_id = self.get_show_id(series, year, country)\n  File "C:\\Python27\\lib\\site-packages\\subliminal\\providers\\addic7ed.py", line 201, in get_show_id\n    show_ids = self._get_show_ids()\n  File "C:\\Python27\\lib\\site-packages\\dogpile\\cache\\region.py", line 1231, in decorate\n    should_cache_fn)\n  File "C:\\Python27\\lib\\site-packages\\dogpile\\cache\\region.py", line 833, in get_or_create\n    async_creator) as value:\n  File "C:\\Python27\\lib\\site-packages\\dogpile\\lock.py", line 154, in __enter__\n    return self._enter()\n  File "C:\\Python27\\lib\\site-packages\\dogpile\\lock.py", line 87, in _enter\n    value = value_fn()\n  File "C:\\Python27\\lib\\site-packages\\dogpile\\cache\\region.py", line 788, in get_value\n    value = self.backend.get(key)\n  File "C:\\Python27\\lib\\site-packages\\dogpile\\cache\\backends\\file.py", line 220, in get\n    with self._dbm_file(False) as dbm:\n  File "C:\\Python27\\lib\\contextlib.py", line 17, in __enter__\n    return self.gen.next()\n  File "C:\\Python27\\lib\\site-packages\\dogpile\\cache\\backends\\file.py", line 212, in _dbm_file\n    with self._use_rw_lock(write):\n  File "C:\\Python27\\lib\\contextlib.py", line 17, in __enter__\n    return self.gen.next()\n  File "C:\\Python27\\lib\\site-packages\\dogpile\\cache\\backends\\file.py", line 207, in _use_rw_lock\n    with self._rw_lock.read():\n  File "C:\\Python27\\lib\\contextlib.py", line 17, in __enter__\n    return self.gen.next()\n  File "C:\\Python27\\lib\\site-packages\\dogpile\\cache\\backends\\file.py", line 327, in read\n    self.acquire_read_lock(True)\n  File "C:\\Python27\\lib\\site-packages\\dogpile\\cache\\backends\\file.py", line 408, in acquire_read_lock\n    return self._acquire(wait, os.O_RDONLY, self._module.LOCK_SH)\n  File "C:\\Python27\\lib\\site-packages\\dogpile\\util\\langhelpers.py", line 66, in __get__\n    obj.__dict__[self.__name__] = result = self.fget(obj)\n  File "C:\\Python27\\lib\\site-packages\\dogpile\\cache\\backends\\file.py", line 400, in _module\n    import fcntl\nImportError: No module named fcntl'|
